
## 记录一次阻塞
改了改程序之后准备测试一下, 但是竟然无法访问 server, 不明所以. 看一下日志库, 发现一条日志也没有, 很是奇怪, 准备调试一下:
strace 输出的最后一部分信息:
```sh
epoll_create1(EPOLL_CLOEXEC)            = 3
eventfd2(0, EFD_CLOEXEC|EFD_NONBLOCK)   = 4
epoll_ctl(3, EPOLL_CTL_ADD, 4, {0, {u32=32292128, u64=32292128}}) = 0
mmap(NULL, 4001792, PROT_READ|PROT_WRITE, MAP_PRIVATE|MAP_ANONYMOUS, -1, 0) = 0x7f1594ada000
mmap(NULL, 4001792, PROT_READ|PROT_WRITE, MAP_PRIVATE|MAP_ANONYMOUS, -1, 0) = 0x7f1594709000
mmap(NULL, 8392704, PROT_READ|PROT_WRITE, MAP_PRIVATE|MAP_ANONYMOUS|MAP_STACK, -1, 0) = 0x7f1593f08000
mprotect(0x7f1593f08000, 4096, PROT_NONE) = 0
clone(child_stack=0x7f1594707fb0, flags=CLONE_VM|CLONE_FS|CLONE_FILES|CLONE_SIGHAND|CLONE_THREAD|CLONE_SYSVSEM|CLONE_SETTLS|CLONE_PARENT_SETTID|CLONE_CHILD_CLEARTID, parent_tidptr=0x7f15947089d0, tls=0x7f1594708700, child_tidptr=0x7f15947089d0) = 19197
futex(0x64da24, FUTEX_WAIT_PRIVATE, 1, NULL) = ? ERESTARTSYS (To be restarted if SA_RESTART is set)
--- SIGWINCH {si_signo=SIGWINCH, si_code=SI_KERNEL} ---
futex(0x64da24, FUTEX_WAIT_PRIVATE, 1, NULL) = ? ERESTARTSYS (To be restarted if SA_RESTART is set)
--- SIGWINCH {si_signo=SIGWINCH, si_code=SI_KERNEL} ---
futex(0x64da24, FUTEX_WAIT_PRIVATE, 1, NULL
```
看最后是阻塞在了 futex, 是发生了死锁, 哪里出了问题?

用 gdb 看的话, 有:
```sh
Thread 1 "httptest" received signal SIGINT, Interrupt.
0x00007ffff7bc8a4f in futex_wait (private=0, expected=1, 
    futex_word=0x64da24 <yxalp::once_>)
```
pthread_once 的原因? `futex_word` 其中 once_ 是一个 static 全局变量

查看一下各个线程现在的状态:
(gdb) info threads 
  Id   Target Id         Frame 
* 1    Thread 0x7ffff7fac740 (LWP 22432) "httptest" 0x00007ffff7bc8a4f in futex_wait (private=0, expected=1, futex_word=0x64da24 <yxalp::once_>)
    at ../sysdeps/unix/sysv/linux/futex-internal.h:61
  2    Thread 0x7ffff67ac700 (LWP 22436) "httptest" pthread_cond_timedwait@@GLIBC_2.3.2 () at ../sysdeps/unix/sysv/linux/x86_64/pthread_cond_timedwait.S:225
很明显只启动了两个线程, 那么就是主线程与 asynclogger 之间或者线程内部出现了死锁. 
看一下主线程的调用堆栈:
```sh
(gdb) bt
#0  0x00007ffff7bc8a4f in futex_wait (private=0, expected=1, 
    futex_word=0x64da24 <yxalp::once_>)
    at ../sysdeps/unix/sysv/linux/futex-internal.h:61
#1  futex_wait_simple (private=0, expected=1, 
    futex_word=0x64da24 <yxalp::once_>) at ../sysdeps/nptl/futex-internal.h:135
#2  __pthread_once_slow (once_control=0x64da24 <yxalp::once_>, 
    init_routine=0x40a140 <yxalp::Init_()>) at pthread_once.c:105
#3  0x000000000040a419 in yxalp::Logger::~Logger (this=0x7fffffffb0b0, 
    __in_chrg=<optimized out>) at ../logger/logging.cc:58
#4  0x000000000040aaa1 in yxalp::Thread::Start (this=0x65fe28)
    at ../thread/thread.cc:87
#5  0x000000000040a6a3 in yxalp::AsyncLogging::Start (this=0x65fe00)
    at ../logger/asynclogging.h:33
#6  0x000000000040a1a9 in yxalp::Init_ () at ../logger/logging.cc:23
#7  0x00007ffff7bc8a99 in __pthread_once_slow (
    once_control=0x64da24 <yxalp::once_>, 
    init_routine=0x40a140 <yxalp::Init_()>) at pthread_once.c:116
#8  0x000000000040a419 in yxalp::Logger::~Logger (this=0x7fffffffc220, 
    __in_chrg=<optimized out>) at ../logger/logging.cc:58
#9  0x000000000040f590 in yxalp::Dispatcher::Dispatcher (this=0x7fffffffd270)
    at ../reactor/dispatcher.cc:46
#10 0x000000000042e8a5 in main (argc=1, argv=0x7fffffffd4d8) at httptest.cc:55
```
因为是在 Logger::~Logger() 中创建日志线程, 所以能看到 `#3 yxalp::Logger::~Logger`, 但是 在 `# 8` 又出现了一次 `yxalp::Logger::~Logger`, 这个情况有点明显了, 在第一个析构函数没退栈的时候, pthread_once 得到的 futex 还没有释放, 第二个析构函数又过来想要得到 futex, 从而发生了死锁(自己把自己锁上了), 但是为什么会尝试在析构中再次执行析构?

再看一下另一个线程吧? 它此时阻塞在 `pthread_cond_timedwait` 上, 比较正常, 那就是主线程中出现的问题了.
(gdb) thread 2
```sh
[Switching to thread 2 (Thread 0x7ffff67ac700 (LWP 22436))]
#0  pthread_cond_timedwait@@GLIBC_2.3.2 ()
    at ../sysdeps/unix/sysv/linux/x86_64/pthread_cond_timedwait.S:225
225	../sysdeps/unix/sysv/linux/x86_64/pthread_cond_timedwait.S: 没有那个文件或目录.
(gdb) bt
#0  pthread_cond_timedwait@@GLIBC_2.3.2 ()
    at ../sysdeps/unix/sysv/linux/x86_64/pthread_cond_timedwait.S:225
#1  0x0000000000405be6 in yxalp::Condition::waitForSeconds (this=0x65ff30, 
    seconds=3) at ../thread/condition.h:42
#2  0x00000000004053a5 in yxalp::AsyncLogging::ThreadFunc (this=0x65fe00)
    at ../logger/asynclogging.cc:61

.....

#8  0x000000000040acc1 in yxalp::ThreadData::RunInThread (this=0x660080)
---Type <return> to continue, or q <return> to quit---
    at ../thread/thread.cc:45
#9  0x000000000040a77b in yxalp::StartRoutine (arg=0x660080)
    at ../thread/thread.cc:52
#10 0x00007ffff7bc16ba in start_thread (arg=0x7ffff67ac700)
    at pthread_create.c:333
#11 0x00007ffff735f41d in clone ()
    at ../sysdeps/unix/sysv/linux/x86_64/clone.S:109
```
回头看一下, 是 `#4 yxalp::Thread::Start` 中又调用 logger 的析构, 回到该函数看一下, 发现在之前改写的时候, 尝试在 Thread::Start() 中 `LOG` 日志, 所以是主线程在创建线程的Routine 中(此时还没释放 futex), 再次尝试获取 futex, 从而发生死锁. 删掉这条 info 型的 log 就好了 :)
